[2022-10-26T00:37:26.952+0000] {taskinstance.py:1165} INFO - Dependencies all met for <TaskInstance: sales_datawarehouse.create_tables manual__2022-10-26T00:35:08.956458+00:00 [queued]>
[2022-10-26T00:37:26.970+0000] {taskinstance.py:1165} INFO - Dependencies all met for <TaskInstance: sales_datawarehouse.create_tables manual__2022-10-26T00:35:08.956458+00:00 [queued]>
[2022-10-26T00:37:26.971+0000] {taskinstance.py:1362} INFO - 
--------------------------------------------------------------------------------
[2022-10-26T00:37:26.972+0000] {taskinstance.py:1363} INFO - Starting attempt 2 of 3
[2022-10-26T00:37:26.973+0000] {taskinstance.py:1364} INFO - 
--------------------------------------------------------------------------------
[2022-10-26T00:37:26.994+0000] {taskinstance.py:1383} INFO - Executing <Task(PostgresOperator): create_tables> on 2022-10-26 00:35:08.956458+00:00
[2022-10-26T00:37:26.999+0000] {standard_task_runner.py:54} INFO - Started process 3570 to run task
[2022-10-26T00:37:27.003+0000] {standard_task_runner.py:82} INFO - Running: ['***', 'tasks', 'run', 'sales_datawarehouse', 'create_tables', 'manual__2022-10-26T00:35:08.956458+00:00', '--job-id', '604', '--raw', '--subdir', 'DAGS_FOLDER/sales_dw.py', '--cfg-path', '/tmp/tmp_mrvtk32']
[2022-10-26T00:37:27.005+0000] {standard_task_runner.py:83} INFO - Job 604: Subtask create_tables
[2022-10-26T00:37:27.007+0000] {dagbag.py:525} INFO - Filling up the DagBag from /opt/***/dags/sales_dw.py
[2022-10-26T00:37:27.840+0000] {task_command.py:384} INFO - Running <TaskInstance: sales_datawarehouse.create_tables manual__2022-10-26T00:35:08.956458+00:00 [running]> on host 83cd0ab98720
[2022-10-26T00:37:27.962+0000] {taskinstance.py:1592} INFO - Exporting the following env vars:
AIRFLOW_CTX_DAG_OWNER=pedromenegat
AIRFLOW_CTX_DAG_ID=sales_datawarehouse
AIRFLOW_CTX_TASK_ID=create_tables
AIRFLOW_CTX_EXECUTION_DATE=2022-10-26T00:35:08.956458+00:00
AIRFLOW_CTX_TRY_NUMBER=2
AIRFLOW_CTX_DAG_RUN_ID=manual__2022-10-26T00:35:08.956458+00:00
[2022-10-26T00:37:27.973+0000] {base.py:71} INFO - Using connection ID '***_localhost' for task execution.
[2022-10-26T00:37:28.096+0000] {sql.py:315} INFO - Running statement: 
        CREATE TABLE IF NOT EXISTS dimFuncionarios(		
            id_funcionario INTEGER PRIMARY KEY NOT NULL,
            nome_funcionario VARCHAR(30) NOT NULL
	    );
        CREATE TABLE IF NOT EXISTS dimCategorias(		
            id INTEGER PRIMARY KEY NOT NULL,
            nome_categoria VARCHAR(30) NOT NULL
		);		
		CREATE TABLE IF NOT EXISTS fatoVendas(
            id_venda INTEGER PRIMARY KEY NOT NULL,
            id_funcionario INTEGER NOT NULL,
            id_categoria INTEGER NOT NULL,
            data_venda DATE NOT NULL,
            venda NUMERIC(20,5) NOT NULL,
            FOREIGN KEY (id_funcionario) 
                REFERENCES funcionarios (id_funcionario)
                ON UPDATE CASCADE ON DELETE CASCADE,
            FOREIGN KEY (id_categoria) 
                REFERENCES categorias (id)
                ON UPDATE CASCADE ON DELETE CASCADE
		);
        , parameters: None
[2022-10-26T00:37:28.137+0000] {taskinstance.py:1851} ERROR - Task failed with exception
Traceback (most recent call last):
  File "/home/airflow/.local/lib/python3.7/site-packages/airflow/providers/postgres/operators/postgres.py", line 94, in execute
    self.hook.run(self.sql, self.autocommit, parameters=self.parameters)
  File "/home/airflow/.local/lib/python3.7/site-packages/airflow/providers/common/sql/hooks/sql.py", line 295, in run
    self._run_command(cur, sql_statement, parameters)
  File "/home/airflow/.local/lib/python3.7/site-packages/airflow/providers/common/sql/hooks/sql.py", line 320, in _run_command
    cur.execute(sql_statement)
psycopg2.errors.UndefinedTable: relation "funcionarios" does not exist

[2022-10-26T00:37:28.151+0000] {taskinstance.py:1406} INFO - Marking task as UP_FOR_RETRY. dag_id=sales_datawarehouse, task_id=create_tables, execution_date=20221026T003508, start_date=20221026T003726, end_date=20221026T003728
[2022-10-26T00:37:28.171+0000] {standard_task_runner.py:107} ERROR - Failed to execute job 604 for task create_tables (relation "funcionarios" does not exist
; 3570)
[2022-10-26T00:37:28.223+0000] {local_task_job.py:164} INFO - Task exited with return code 1
[2022-10-26T00:37:28.273+0000] {local_task_job.py:273} INFO - 0 downstream tasks scheduled from follow-on schedule check
