[2022-10-26T00:39:31.657+0000] {taskinstance.py:1165} INFO - Dependencies all met for <TaskInstance: sales_datawarehouse.create_tables manual__2022-10-26T00:35:08.956458+00:00 [queued]>
[2022-10-26T00:39:31.687+0000] {taskinstance.py:1165} INFO - Dependencies all met for <TaskInstance: sales_datawarehouse.create_tables manual__2022-10-26T00:35:08.956458+00:00 [queued]>
[2022-10-26T00:39:31.688+0000] {taskinstance.py:1362} INFO - 
--------------------------------------------------------------------------------
[2022-10-26T00:39:31.689+0000] {taskinstance.py:1363} INFO - Starting attempt 3 of 3
[2022-10-26T00:39:31.689+0000] {taskinstance.py:1364} INFO - 
--------------------------------------------------------------------------------
[2022-10-26T00:39:31.719+0000] {taskinstance.py:1383} INFO - Executing <Task(PostgresOperator): create_tables> on 2022-10-26 00:35:08.956458+00:00
[2022-10-26T00:39:31.728+0000] {standard_task_runner.py:54} INFO - Started process 3728 to run task
[2022-10-26T00:39:31.734+0000] {standard_task_runner.py:82} INFO - Running: ['***', 'tasks', 'run', 'sales_datawarehouse', 'create_tables', 'manual__2022-10-26T00:35:08.956458+00:00', '--job-id', '618', '--raw', '--subdir', 'DAGS_FOLDER/sales_dw.py', '--cfg-path', '/tmp/tmp2gy04nz8']
[2022-10-26T00:39:31.736+0000] {standard_task_runner.py:83} INFO - Job 618: Subtask create_tables
[2022-10-26T00:39:31.737+0000] {dagbag.py:525} INFO - Filling up the DagBag from /opt/***/dags/sales_dw.py
[2022-10-26T00:39:42.239+0000] {task_command.py:384} INFO - Running <TaskInstance: sales_datawarehouse.create_tables manual__2022-10-26T00:35:08.956458+00:00 [running]> on host 83cd0ab98720
[2022-10-26T00:39:42.621+0000] {taskinstance.py:1592} INFO - Exporting the following env vars:
AIRFLOW_CTX_DAG_OWNER=pedromenegat
AIRFLOW_CTX_DAG_ID=sales_datawarehouse
AIRFLOW_CTX_TASK_ID=create_tables
AIRFLOW_CTX_EXECUTION_DATE=2022-10-26T00:35:08.956458+00:00
AIRFLOW_CTX_TRY_NUMBER=3
AIRFLOW_CTX_DAG_RUN_ID=manual__2022-10-26T00:35:08.956458+00:00
[2022-10-26T00:39:42.659+0000] {base.py:71} INFO - Using connection ID '***_localhost' for task execution.
[2022-10-26T00:39:42.915+0000] {sql.py:315} INFO - Running statement: 
        CREATE TABLE IF NOT EXISTS dimFuncionarios(		
            id_funcionario INTEGER PRIMARY KEY NOT NULL,
            nome_funcionario VARCHAR(30) NOT NULL
	    );
        CREATE TABLE IF NOT EXISTS dimCategorias(		
            id INTEGER PRIMARY KEY NOT NULL,
            nome_categoria VARCHAR(30) NOT NULL
		);		
		CREATE TABLE IF NOT EXISTS fatoVendas(
            id_venda INTEGER PRIMARY KEY NOT NULL,
            id_funcionario INTEGER NOT NULL,
            id_categoria INTEGER NOT NULL,
            data_venda DATE NOT NULL,
            venda NUMERIC(20,5) NOT NULL,
            FOREIGN KEY (id_funcionario) 
                REFERENCES dimFuncionarios (id_funcionario)
                ON UPDATE CASCADE ON DELETE CASCADE,
            FOREIGN KEY (id_categoria) 
                REFERENCES dimCategorias (id)
                ON UPDATE CASCADE ON DELETE CASCADE
		);
        , parameters: None
[2022-10-26T00:39:42.934+0000] {postgres.py:96} INFO - NOTICE:  relation "dimfuncionarios" already exists, skipping

[2022-10-26T00:39:42.936+0000] {postgres.py:96} INFO - NOTICE:  relation "dimcategorias" already exists, skipping

[2022-10-26T00:39:42.938+0000] {postgres.py:96} INFO - NOTICE:  relation "fatovendas" already exists, skipping

[2022-10-26T00:39:42.996+0000] {taskinstance.py:1406} INFO - Marking task as SUCCESS. dag_id=sales_datawarehouse, task_id=create_tables, execution_date=20221026T003508, start_date=20221026T003931, end_date=20221026T003942
[2022-10-26T00:39:43.150+0000] {local_task_job.py:164} INFO - Task exited with return code 0
[2022-10-26T00:39:43.246+0000] {local_task_job.py:273} INFO - 1 downstream tasks scheduled from follow-on schedule check
