[2022-10-24T19:30:09.851+0000] {taskinstance.py:1165} INFO - Dependencies all met for <TaskInstance: sales_datawarehouse.get_vendas manual__2022-10-24T16:41:40.584519+00:00 [queued]>
[2022-10-24T19:30:09.866+0000] {taskinstance.py:1165} INFO - Dependencies all met for <TaskInstance: sales_datawarehouse.get_vendas manual__2022-10-24T16:41:40.584519+00:00 [queued]>
[2022-10-24T19:30:09.867+0000] {taskinstance.py:1362} INFO - 
--------------------------------------------------------------------------------
[2022-10-24T19:30:09.867+0000] {taskinstance.py:1363} INFO - Starting attempt 2 of 3
[2022-10-24T19:30:09.868+0000] {taskinstance.py:1364} INFO - 
--------------------------------------------------------------------------------
[2022-10-24T19:30:09.891+0000] {taskinstance.py:1383} INFO - Executing <Task(PythonOperator): get_vendas> on 2022-10-24 16:41:40.584519+00:00
[2022-10-24T19:30:09.900+0000] {standard_task_runner.py:54} INFO - Started process 14030 to run task
[2022-10-24T19:30:09.904+0000] {standard_task_runner.py:82} INFO - Running: ['***', 'tasks', 'run', 'sales_datawarehouse', 'get_vendas', 'manual__2022-10-24T16:41:40.584519+00:00', '--job-id', '226', '--raw', '--subdir', 'DAGS_FOLDER/sales_dw.py', '--cfg-path', '/tmp/tmpfv54_trs']
[2022-10-24T19:30:09.906+0000] {standard_task_runner.py:83} INFO - Job 226: Subtask get_vendas
[2022-10-24T19:30:09.907+0000] {dagbag.py:525} INFO - Filling up the DagBag from /opt/***/dags/sales_dw.py
[2022-10-24T19:30:10.539+0000] {task_command.py:384} INFO - Running <TaskInstance: sales_datawarehouse.get_vendas manual__2022-10-24T16:41:40.584519+00:00 [running]> on host 83cd0ab98720
[2022-10-24T19:30:10.632+0000] {taskinstance.py:1592} INFO - Exporting the following env vars:
AIRFLOW_CTX_DAG_OWNER=pedromenegat
AIRFLOW_CTX_DAG_ID=sales_datawarehouse
AIRFLOW_CTX_TASK_ID=get_vendas
AIRFLOW_CTX_EXECUTION_DATE=2022-10-24T16:41:40.584519+00:00
AIRFLOW_CTX_TRY_NUMBER=2
AIRFLOW_CTX_DAG_RUN_ID=manual__2022-10-24T16:41:40.584519+00:00
[2022-10-24T19:30:10.643+0000] {base.py:71} INFO - Using connection ID 'banco_vendas' for task execution.
[2022-10-24T19:30:12.870+0000] {taskinstance.py:1851} ERROR - Task failed with exception
Traceback (most recent call last):
  File "/home/airflow/.local/lib/python3.7/site-packages/airflow/operators/python.py", line 175, in execute
    return_value = self.execute_callable()
  File "/home/airflow/.local/lib/python3.7/site-packages/airflow/operators/python.py", line 193, in execute_callable
    return self.python_callable(*self.op_args, **self.op_kwargs)
  File "/opt/airflow/dags/sales_dw.py", line 23, in get_vendas
    data_vendas = json.dumps(df_vendas)
  File "/usr/local/lib/python3.7/json/__init__.py", line 231, in dumps
    return _default_encoder.encode(obj)
  File "/usr/local/lib/python3.7/json/encoder.py", line 199, in encode
    chunks = self.iterencode(o, _one_shot=True)
  File "/usr/local/lib/python3.7/json/encoder.py", line 257, in iterencode
    return _iterencode(o, 0)
  File "/usr/local/lib/python3.7/json/encoder.py", line 179, in default
    raise TypeError(f'Object of type {o.__class__.__name__} '
TypeError: Object of type DataFrame is not JSON serializable
[2022-10-24T19:30:12.894+0000] {taskinstance.py:1406} INFO - Marking task as UP_FOR_RETRY. dag_id=sales_datawarehouse, task_id=get_vendas, execution_date=20221024T164140, start_date=20221024T193009, end_date=20221024T193012
[2022-10-24T19:30:12.924+0000] {standard_task_runner.py:107} ERROR - Failed to execute job 226 for task get_vendas (Object of type DataFrame is not JSON serializable; 14030)
[2022-10-24T19:30:12.970+0000] {local_task_job.py:164} INFO - Task exited with return code 1
[2022-10-24T19:30:13.053+0000] {local_task_job.py:273} INFO - 0 downstream tasks scheduled from follow-on schedule check
