[2022-10-23T16:18:07.470+0000] {taskinstance.py:1165} INFO - Dependencies all met for <TaskInstance: sales_datawarehouse.query_vendas manual__2022-10-23T16:18:05.466304+00:00 [queued]>
[2022-10-23T16:18:07.484+0000] {taskinstance.py:1165} INFO - Dependencies all met for <TaskInstance: sales_datawarehouse.query_vendas manual__2022-10-23T16:18:05.466304+00:00 [queued]>
[2022-10-23T16:18:07.484+0000] {taskinstance.py:1362} INFO - 
--------------------------------------------------------------------------------
[2022-10-23T16:18:07.485+0000] {taskinstance.py:1363} INFO - Starting attempt 1 of 6
[2022-10-23T16:18:07.486+0000] {taskinstance.py:1364} INFO - 
--------------------------------------------------------------------------------
[2022-10-23T16:18:07.504+0000] {taskinstance.py:1383} INFO - Executing <Task(PostgresOperator): query_vendas> on 2022-10-23 16:18:05.466304+00:00
[2022-10-23T16:18:07.508+0000] {standard_task_runner.py:54} INFO - Started process 726 to run task
[2022-10-23T16:18:07.512+0000] {standard_task_runner.py:82} INFO - Running: ['***', 'tasks', 'run', 'sales_datawarehouse', 'query_vendas', 'manual__2022-10-23T16:18:05.466304+00:00', '--job-id', '11', '--raw', '--subdir', 'DAGS_FOLDER/sales_dw.py', '--cfg-path', '/tmp/tmp6atqbpuk']
[2022-10-23T16:18:07.514+0000] {standard_task_runner.py:83} INFO - Job 11: Subtask query_vendas
[2022-10-23T16:18:07.515+0000] {dagbag.py:525} INFO - Filling up the DagBag from /opt/***/dags/sales_dw.py
[2022-10-23T16:18:07.936+0000] {task_command.py:384} INFO - Running <TaskInstance: sales_datawarehouse.query_vendas manual__2022-10-23T16:18:05.466304+00:00 [running]> on host 499050b57294
[2022-10-23T16:18:08.060+0000] {taskinstance.py:1592} INFO - Exporting the following env vars:
AIRFLOW_CTX_DAG_OWNER=pedromenegat
AIRFLOW_CTX_DAG_ID=sales_datawarehouse
AIRFLOW_CTX_TASK_ID=query_vendas
AIRFLOW_CTX_EXECUTION_DATE=2022-10-23T16:18:05.466304+00:00
AIRFLOW_CTX_TRY_NUMBER=1
AIRFLOW_CTX_DAG_RUN_ID=manual__2022-10-23T16:18:05.466304+00:00
[2022-10-23T16:18:08.075+0000] {base.py:71} INFO - Using connection ID 'banco_vendas' for task execution.
[2022-10-23T16:18:09.654+0000] {sql.py:315} INFO - Running statement: 
            SELECT * FROM vendas;
        , parameters: None
[2022-10-23T16:18:10.080+0000] {taskinstance.py:1851} ERROR - Task failed with exception
Traceback (most recent call last):
  File "/home/airflow/.local/lib/python3.7/site-packages/airflow/providers/postgres/operators/postgres.py", line 94, in execute
    self.hook.run(self.sql, self.autocommit, parameters=self.parameters)
  File "/home/airflow/.local/lib/python3.7/site-packages/airflow/providers/common/sql/hooks/sql.py", line 295, in run
    self._run_command(cur, sql_statement, parameters)
  File "/home/airflow/.local/lib/python3.7/site-packages/airflow/providers/common/sql/hooks/sql.py", line 320, in _run_command
    cur.execute(sql_statement)
psycopg2.errors.UndefinedTable: relation "vendas" does not exist
LINE 2:             SELECT * FROM vendas;
                                  ^

[2022-10-23T16:18:10.124+0000] {taskinstance.py:1406} INFO - Marking task as UP_FOR_RETRY. dag_id=sales_datawarehouse, task_id=query_vendas, execution_date=20221023T161805, start_date=20221023T161807, end_date=20221023T161810
[2022-10-23T16:18:10.189+0000] {standard_task_runner.py:107} ERROR - Failed to execute job 11 for task query_vendas (relation "vendas" does not exist
LINE 2:             SELECT * FROM vendas;
                                  ^
; 726)
[2022-10-23T16:18:10.266+0000] {local_task_job.py:164} INFO - Task exited with return code 1
[2022-10-23T16:18:10.384+0000] {local_task_job.py:273} INFO - 0 downstream tasks scheduled from follow-on schedule check
